<?xml version="1.0"?>

<robot name="robot_arm">
    <link name="world"/>

    <!-- BASE LINK-->
    <link name="base_link">
        <visual>
            <geometry>
                <cylinder radius="0.8" length="0.3"/>
            </geometry>
            <material name="Black"/>
            <origin xyz="0.0 0.0 0.15" rpy="0.0 0.0 0.0"/>
        </visual>
        <collision>
            <geometry>
                <cylinder radius="0.8" length="0.3"/>
            </geometry>
            <origin xyz="0.0 0.0 0.15" rpy="0.0 0.0 0.0"/>
        </collision>
        <inertial>
            <mass value="1"/>
            <origin xyz="0.0 0.0 0.15"/>
            <inertia ixx="0.0027" izz="0.005" iyy="0.0027" ixy="0.0" ixz="0.0"  iyz="0.0" />
        </inertial>
    </link>

    <joint name="fixed_base" type="fixed">
        <parent link="world"/>
        <child link="base_link"/>
        
    </joint>

    <!-- FIRST LINK-->
    <link name="First">
        <visual>
            <geometry>
                <cylinder radius="0.4" length="0.5"/>
            </geometry>
            <material name="Orange">
                <color rgba="1.0 0.5 0.15 1.0"/>
            </material>
            <origin xyz="0.0 0.0 0.25" rpy="0.0 0.0 0.0"/>
        </visual>
        <collision>
            <geometry>
                <cylinder radius="0.4" length="0.5"/>
            </geometry>
            <origin xyz="0.0 0.0 0.25" rpy="0.0 0.0 0.0"/>
        </collision>
        <inertial>
            <mass value="1"/>
            <origin xyz="0.0 0.0 0.25" rpy="0.0 0.0 0.0"/>
            <inertia ixx="0.02176" izz="0.00125" iyy="0.02146" ixy="0.0" ixz="0.0"  iyz="0.0" />
        </inertial>
    </link>

    <joint name="First_joint" type="continuous">
        <limit lower="-3.14" upper="3.14" effort="100.0" velocity="1.0"/>
        <parent link="base_link"/>
        <child link="First"/>
        <axis xyz="0.0 0.0 1"/>
        <origin xyz="0.0 0.0 0.3" rpy="0.0 0.0 0.0"/>
        
    </joint>

    <!-- SECOND LINK-->
    <link name="Second">
        <visual>
            <geometry>
                <cylinder radius="0.15" length="0.5"/>
            </geometry>
            <material name="Orange">
                <color rgba="1.0 0.5 0.15 1.0"/>
            </material>
            <origin xyz="0.0 0.0 0.25" rpy="0.0 0.0 0.0"/>
        </visual>
        <collision>
            <geometry>
                <cylinder radius="0.3" length="0.5"/>
            </geometry>
            <origin xyz="0.0 0.0 0.25" rpy="0.0 0.0 0.0"/>
        </collision>
        <inertial>
            <mass value="1"/>
            <origin xyz="0.0 0.0 0.25" rpy="0.0 0.0 0.0"/>
            <inertia ixx="0.01396" izz="0.0015" iyy="0.01396" ixy="0.0" ixz="0.0"  iyz="0.0" />
        </inertial>
    </link>

    <joint name="Second_joint" type="fixed">
        <parent link="First"/>
        <child link="Second"/>
        <axis xyz="0.0 0.0 1"/>
        <origin xyz="0.0 0 0.5" rpy="0.0 1.5708 0"/>        
    </joint>

    <!-- THIRD LINK-->
    <link name="Third">
        <visual>
            <geometry>
                <cylinder radius="0.15" length="1.3"/>
            </geometry>
            <material name="Orange">
                <color rgba="1.0 0.5 0.15 1.0"/>
            </material>
            <origin xyz="0.0 0.0 0.65" rpy="0.0 0.0 0.0"/>
        </visual>
        <collision>
            <geometry>
                <cylinder radius="0.3" length="1.3"/>
            </geometry>
            <origin xyz="0.0 0.0 0.65" rpy="0.0 0.0 0.0"/>
        </collision>
        <inertial>
            <mass value="1"/>
            <origin xyz="0.0 0.0 0.65" rpy="0.0 0.0 0.0"/>
            <inertia ixx="0.01396" izz="0.0015" iyy="0.01396" ixy="0.0" ixz="0.0"  iyz="0.0" />
        </inertial>
    </link>

    <joint name="Third_joint" type="continuous">
        <limit lower="-3.14" upper="3.14" effort="100.0" velocity="1.0"/>
        <parent link="Second"/>
        <child link="Third"/>
        <axis xyz="0 1 0"/>
        <origin xyz="0.0 0 0.5" rpy="0.0 -1.5708 0"/>        
    </joint>

    <!-- FOURTH LINK-->
    <link name="Fourth">
        <visual>
            <geometry>
                <cylinder radius="0.15" length="0.5"/>
            </geometry>
            <material name="Orange">
                <color rgba="1.0 0.5 0.15 1.0"/>
            </material>
            <origin xyz="0.0 0.0 0.25" rpy="0.0 0.0 0.0"/>
        </visual>
        <collision>
            <geometry>
                <cylinder radius="0.15" length="0.5"/>
            </geometry>
            <origin xyz="0.0 0.0 0.25" rpy="0.0 0.0 0.0"/>
        </collision>
        <inertial>
            <mass value="1"/>
            <origin xyz="0.0 0.0 0.25" rpy="0.0 0.0 0.0"/>
            <inertia ixx="0.01396" izz="0.0015" iyy="0.01396" ixy="0.0" ixz="0.0"  iyz="0.0" />
        </inertial>
    </link>

    <joint name="Fourth_joint" type="continuous">
        <limit lower="-3.14" upper="3.14" effort="100.0" velocity="1.0"/>
        <parent link="Third"/>
        <child link="Fourth"/>
        <axis xyz="0 1 0"/>
        <origin xyz="0.0 0 1.3" rpy="0.0 1.5708 0"/>        
    </joint>


    <!-- FIFTH LINK-->
    <link name="Fifth">
        <visual>
            <geometry>
                <cylinder radius="0.1" length="0.5"/>
            </geometry>
            <material name="Orange">
                <color rgba="1.0 0.5 0.15 1.0"/>
            </material>
            <origin xyz="0.0 0.0 0.25" rpy="0.0 0.0 0.0"/>
        </visual>
        <collision>
            <geometry>
                <cylinder radius="0.1" length="0.5"/>
            </geometry>
            <origin xyz="0.0 0.0 0.25" rpy="0.0 0.0 0.0"/>
        </collision>
        <inertial>
            <mass value="1"/>
            <origin xyz="0.0 0.0 0.25" rpy="0.0 0.0 0.0"/>
            <inertia ixx="0.01396" izz="0.0015" iyy="0.01396" ixy="0.0" ixz="0.0"  iyz="0.0" />
        </inertial>
    </link>

    <joint name="Fifth_joint" type="continuous">
        <limit lower="-3.14" upper="3.14" effort="100.0" velocity="1.0"/>
        <parent link="Fourth"/>
        <child link="Fifth"/>
        <axis xyz="0 0 1"/>
        <origin xyz="0.0 0 0.5" rpy="0.0 0 0"/>        
    </joint>

    <!-- SIXTH LINK-->
    <link name="Sixth">
        <visual>
            <geometry>
                <cylinder radius="0.075" length="0.29"/>
            </geometry>
            <material name="Orange">
                <color rgba="1.0 0.5 0.15 1.0"/>
            </material>
            <origin xyz="0.0 0.0 0.145" rpy="0.0 0.0 0.0"/>
        </visual>
        <collision>
            <geometry>
                <cylinder radius="0.075" length="0.29"/>
            </geometry>
            <origin xyz="0.0 0.0 0.145" rpy="0.0 0.0 0.0"/>
        </collision>
        <inertial>
            <mass value="1"/>
            <origin xyz="0.0 0.0 0.145" rpy="0.0 0.0 0.0"/>
            <inertia ixx="0.01396" izz="0.0015" iyy="0.01396" ixy="0.0" ixz="0.0"  iyz="0.0" />
        </inertial>
    </link>

    <joint name="Sixth_joint" type="continuous">
        <limit lower="-3.14" upper="3.14" effort="100.0" velocity="1.0"/>
        <parent link="Fifth"/>
        <child link="Sixth"/>
        <axis xyz="0 1 0"/>
        <origin xyz="0.0 0 0.5" rpy="0.0 0 0"/>        
    </joint>


    <!-- GRIPPER_BASE LINK-->
    <link name="Gripper_Base">
        <visual>
            <geometry>
                <cylinder radius="0.1" length="0.05"/>
            </geometry>
            <material name="Black"/>
            <origin xyz="0.0 0.0 0.025" rpy="0.0 0.0 0.0"/>
        </visual>
        <collision>
            <geometry>
                <cylinder radius="0.08" length="0.05"/>
            </geometry>
            <origin xyz="0.0 0.0 0.025" rpy="0.0 0.0 0.0"/>
        </collision>
        <inertial>
            <mass value="1"/>
            <origin xyz="0.0 0.0 0.025" rpy="0.0 0.0 0.0"/>
            <inertia ixx="0.01396" izz="0.00125" iyy="0.01396" ixy="0.0" ixz="0.0"  iyz="0.0" />
        </inertial>
    </link>

    <joint name="Gripper_Base_joint" type="continuous">
        <limit lower="-3.14" upper="3.14" effort="100.0" velocity="1.0"/>
        <parent link="Sixth"/>
        <child link="Gripper_Base"/>
        <axis xyz="0.0 0.0 1"/>
        <origin xyz="0.0 0 0.29" rpy="0.0 0 0"/>        
    </joint>

    <!-- LEFT FINGER LINK-->
    <link name="Left_Finger">
            <visual>
                <geometry>
                    <box size="0.02 0.02 0.15"/>
                </geometry>
                <material name="Red">
                    <color rgba="1.0 0.0 0.0 1.0"/>
                </material>
                <origin xyz="0.0 0.0 0.075" rpy="0.0 0.0 0.0"/>
            </visual>
            <collision>
                <geometry>
                    <box size="0.02 0.02 0.15"/>
                </geometry>
                <origin xyz="0.0 0.0 0.075" rpy="0.0 0.0 0.0"/>
            </collision>
            <inertial>
                <mass value="1"/>
                <origin xyz="0.0 0.0 0.075" rpy="0.0 0.0 0.0"/>
                <inertia ixx="0.1" izz="0.0015" iyy="0.1" ixy="0.0" ixz="0.0"  iyz="0.0" />
            </inertial>
    </link>

    <joint name="Left_Finger_joint" type="prismatic">
        <limit lower="-0.02" upper="0.02" effort="100.0" velocity="1.0"/>
        <parent link="Gripper_Base"/>
        <child link="Left_Finger"/>
        <axis xyz="0.0 1 0"/>
        <origin xyz="0.0 -0.04 0.05" />        
    </joint>

    <!-- RIGHT FINGER LINK-->
    <link name="Right_Finger">
        <visual>
            <geometry>
                <box size="0.02 0.02 0.15"/>
            </geometry>
                <material name="Red">
                    <color rgba="1.0 0.0 0.0 1.0"/>
                </material>
            <origin xyz="0.0 0.0 0.075" rpy="0.0 0.0 0.0"/>
        </visual>
        <collision>
            <geometry>
                <box size="0.02 0.02 0.15"/>
            </geometry>
            <origin xyz="0.0 0.0 0.075" rpy="0.0 0.0 0.0"/>
        </collision>
        <inertial>
            <mass value="1"/>
            <origin xyz="0.0 0.0 0.075" rpy="0.0 0.0 0.0"/>
            <inertia ixx="0.1" izz="0.0015" iyy="0.1" ixy="0.0" ixz="0.0"  iyz="0.0" />
        </inertial>
    </link>

    <joint name="Right_Finger_joint" type="prismatic">
        <limit lower="-0.02" upper="0.02" effort="100.0" velocity="1.0"/>
        <parent link="Gripper_Base"/>
        <child link="Right_Finger"/>
        <axis xyz="0.0 -1 0"/>
        <origin xyz="0.0 0.04 0.05" />        
    </joint>

    
    <!--TRANSMISSIONS-->
    <!--First-->
    <transmission name ="Transmission_1">
        <type>transmission_interface/SimpleTransmission</type>
        <joint name="First_joint">
            <hardwareInterface>hardware_interface/PositionJointInterface</hardwareInterface>
        </joint>
        <actuator name="Motor1">
            <hardwareInterface>hardware_interface/PositionJointInterface</hardwareInterface>
            <mechanicalReduction>1</mechanicalReduction>
        </actuator>
    </transmission>

    <!--Third-->
    <transmission name ="Transmission_3">
        <type>transmission_interface/SimpleTransmission</type>
        <joint name="Third_joint">
            <hardwareInterface>hardware_interface/PositionJointInterface</hardwareInterface>
        </joint>
        <actuator name="Motor3">
            <hardwareInterface>hardware_interface/PositionJointInterface</hardwareInterface>
            <mechanicalReduction>1</mechanicalReduction>
        </actuator>
    </transmission>


    <!--Fourth-->
    <transmission name="Transmission_4">
        <type>transmission_interface/SimpleTransmission</type>
        <joint name="Fourth_joint">
            <hardwareInterface>hardware_interface/PositionJointInterface</hardwareInterface>
        </joint>
        <actuator name="Motor4">
            <hardwareInterface>hardware_interface/PositionJointInterface</hardwareInterface>
            <mechanicalReduction>1</mechanicalReduction>
        </actuator>
    </transmission>

    <!--Fifth-->
    <transmission name="Transmission_5">
        <type>transmission_interface/SimpleTransmission</type>
        <joint name="Fifth_joint">
            <hardwareInterface>hardware_interface/PositionJointInterface</hardwareInterface>
        </joint>
        <actuator name="Motor5">
            <hardwareInterface>hardware_interface/PositionJointInterface</hardwareInterface>
            <mechanicalReduction>1</mechanicalReduction>
        </actuator>
    </transmission>

    <!--Sixth-->
    <transmission name="Transmission_6">
        <type>transmission_interface/SimpleTransmission</type>
        <joint name="Sixth_joint">
            <hardwareInterface>hardware_interface/PositionJointInterface</hardwareInterface>
        </joint>
        <actuator name="Motor6">
            <hardwareInterface>hardware_interface/PositionJointInterface</hardwareInterface>
            <mechanicalReduction>1</mechanicalReduction>
        </actuator>
    </transmission>

    <!--Gripper base-->
    <transmission name="Transmission_7">
        <type>transmission_interface/SimpleTransmission</type>
        <joint name="Gripper_Base_joint">
            <hardwareInterface>hardware_interface/PositionJointInterface</hardwareInterface>
        </joint>
        <actuator name="Motor7">
            <hardwareInterface>hardware_interface/PositionJointInterface</hardwareInterface>
            <mechanicalReduction>1</mechanicalReduction>
        </actuator>
    </transmission>

    <!--Left finger-->
    <transmission name="Transmission_8">
        <type>transmission_interface/SimpleTransmission</type>
        <joint name="Left_Finger_joint">
            <hardwareInterface>hardware_interface/PositionJointInterface</hardwareInterface>
        </joint>
        <actuator name="Motor8">
            <hardwareInterface>hardware_interface/PositionJointInterface</hardwareInterface>
            <mechanicalReduction>1</mechanicalReduction>
        </actuator>
    </transmission>

    <!--Right finger-->
    <transmission name="Transmission_9">
        <type>transmission_interface/SimpleTransmission</type>
        <joint name="Right_Finger_joint">
            <hardwareInterface>hardware_interface/PositionJointInterface</hardwareInterface>
        </joint>
        <actuator name="Motor9">
            <hardwareInterface>hardware_interface/PositionJointInterface</hardwareInterface>
            <mechanicalReduction>1</mechanicalReduction>
        </actuator>
    </transmission>


    <gazebo>
        <plugin name="gazebo_ros_control" filename="libgazebo_ros_control.so">
            <robotNamespace>/robot_arm</robotNamespace>
        </plugin>
    </gazebo>        
    

    <gazebo>
        <plugin name="joint_state_publisher" filename="libgazebo_ros_joint_state_publisher.so">
            <jointName>First_joint, Third_joint, Fourth_joint, Fifth_joint, Sixth_joint, Gripper_Base_joint, Left_Finger_joint, Right_Finger_joint</jointName>
        </plugin>
    </gazebo>

</robot>
