<?xml version="1.0"?>

<robot name="robot_arm">
    <link name="world"/>

    <!-- BASE LINK-->
    <link name="base_link">
        <visual>
            <geometry>
                <cylinder radius="0.8" length="0.3"/>
            </geometry>
            <material name="Black"/>
            <origin xyz="0.0 0.0 0.15" rpy="0.0 0.0 0.0"/>
        </visual>
        <collision>
            <geometry>
                <cylinder radius="0.8" length="0.3"/>
            </geometry>
            <origin xyz="0.0 0.0 0.15" rpy="0.0 0.0 0.0"/>
        </collision>
        <inertial>
            <mass value="1"/>
            <origin xyz="0.0 0.0 0.15"/>
            <inertia ixx="0.0027" ixy="0.0" ixz="0.0" 
                     iyy="0.0027" iyz="0.0"
                     izz="0.005"/>
        </inertial>
    </link>

    <joint name="fixed_base" type="fixed">
        <parent link="world"/>
        <child link="base_link"/>
        
    </joint>

    <!-- FIRST LINK-->
    <link name="First">
        <visual>
            <geometry>
                <!--cylinder radius="0.4" length="0.5"/-->
                <mesh filename = "package://hurba_robot_arm/meshes/Link_1.dae"/>
            </geometry>
            <material name="Orange">
                <color rgba="1.0 0.5 0.15 1.0"/>
            </material>
            <origin xyz="0.0 0.0 0.25" rpy="0.0 0.0 0.0"/>
        </visual>
        <collision>
            <geometry>
                <cylinder radius="0.4" length="0.5"/>
            </geometry>
            <origin xyz="0.0 0.0 0.25" rpy="0.0 0.0 0.0"/>
        </collision>
        <inertial>
            <mass value="50"/>
            <origin xyz="0.0 0.0 0.25" rpy="0.0 0.0 0.0"/>
            <inertia ixx="3.04166545" ixy="0.0" ixz="0.0"
                     iyy="3.04166545" iyz="0.0"
                     izz="4.0"/>
        </inertial>
    </link>

    <joint name="First_joint" type="continuous">
        <limit lower="-3.14" upper="3.14" effort="5000.0" velocity="1.0"/>
        <parent link="base_link"/>
        <child link="First"/>
        <axis xyz="0.0 0.0 1"/>
        <origin xyz="0.0 0.0 0.3" rpy="0.0 0.0 0.0"/>
        <dynamics damping="0.7"/>
        
    </joint>

    <!-- SECOND LINK-->
    <link name="Second">
        <visual>
            <geometry>
                <!--cylinder radius="0.15" length="0.5"/-->
                <mesh filename = "package://hurba_robot_arm/meshes/Link_2.dae"/>
            </geometry>
            <material name="Orange">
                <color rgba="1.0 0.5 0.15 1.0"/>
            </material>
            <origin xyz="0.0 0.0 0.25" rpy="0.0 0.0 0.0"/>
        </visual>
        <collision>
            <geometry>
                <cylinder radius="0.3" length="0.5"/>
            </geometry>
            <origin xyz="0.0 0.0 0.25" rpy="0.0 0.0 0.0"/>
        </collision>
        <inertial>
            <mass value="10"/>
            <origin xyz="0.0 0.0 0.25" rpy="0.0 0.0 0.0"/>
            <inertia ixx="0.264583228" ixy="0.0" ixz="0.0" 
                     iyy="0.264583228" iyz="0.0"
                     izz="0.1125"/>
        </inertial>
    </link>

    <joint name="Second_joint" type="fixed">
        <parent link="First"/>
        <child link="Second"/>
        <axis xyz="0.0 0.0 1"/>
        <origin xyz="0.0 0 0.5" rpy="0.0 1.5708 0"/>
        <dynamics damping="0.7"/>        
    </joint>

    <!-- THIRD LINK-->
    <link name="Third">
        <visual>
            <geometry>
                <!--cylinder radius="0.15" length="1.3"/-->
                <mesh filename = "package://hurba_robot_arm/meshes/Link_3.dae"/>
            </geometry>
            <material name="Orange">
                <color rgba="1.0 0.5 0.15 1.0"/>
            </material>
            <origin xyz="0.0 0.0 0.65" rpy="0.0 0.0 0.0"/>
        </visual>
        <collision>
            <geometry>
                <cylinder radius="0.3" length="1.3"/>
            </geometry>
            <origin xyz="0.0 0.0 0.65" rpy="0.0 0.0 0.0"/>
        </collision>
        <inertial>
            <mass value="10"/>
            <origin xyz="0.0 0.0 0.65" rpy="0.0 0.0 0.0"/>
            <inertia ixx="1.464582748" ixy="0.0" ixz="0.0"
                     iyy="1.464582748" iyz="0.0"
                     izz="0.1125"  />
        </inertial>
    </link>

    <joint name="Third_joint" type="continuous">
        <limit lower="-3.14" upper="3.14" effort="3000.0" velocity="1.0"/>
        <parent link="Second"/>
        <child link="Third"/>
        <axis xyz="0 1 0"/>
        <origin xyz="0.0 0 0.5" rpy="0.0 -1.5708 0"/>
        <dynamics damping="0.7"/>        
    </joint>

    <!-- FOURTH LINK-->
    <link name="Fourth">
        <visual>
            <geometry>
                <!--cylinder radius="0.15" length="0.5"/-->
                <mesh filename = "package://hurba_robot_arm/meshes/Link_4.dae"/>
            </geometry>
            <material name="Orange">
                <color rgba="1.0 0.5 0.15 1.0"/>
            </material>
            <origin xyz="0.0 0.0 0.25" rpy="0.0 0.0 0.0"/>
        </visual>
        <collision>
            <geometry>
                <cylinder radius="0.15" length="0.5"/>
            </geometry>
            <origin xyz="0.0 0.0 0.25" rpy="0.0 0.0 0.0"/>
        </collision>
        <inertial>
            <mass value="7"/>
            <origin xyz="0.0 0.0 0.25" rpy="0.0 0.0 0.0"/>
            <inertia ixx="0.185208259" ixy="0.0" ixz="0.0"
                     iyy="0.185208259" iyz="0.0"
                     izz="0.07875"/>
        </inertial>
    </link>

    <joint name="Fourth_joint" type="continuous">
        <limit lower="-3.14" upper="3.14" effort="3000.0" velocity="1.0"/>
        <parent link="Third"/>
        <child link="Fourth"/>
        <axis xyz="0 1 0"/>
        <origin xyz="0.0 0 1.3" rpy="0.0 1.5708 0"/>
        <dynamics damping="0.7"/>
        <selfCollide>false</selfCollide>    
    </joint>


    <!-- FIFTH LINK-->
    <link name="Fifth">
        <visual>
            <geometry>
                <cylinder radius="0.1" length="0.5"/>
            </geometry>
            <material name="Orange">
                <color rgba="1.0 0.5 0.15 1.0"/>
            </material>
            <origin xyz="0.0 0.0 0.25" rpy="0.0 0.0 0.0"/>
        </visual>
        <collision>
            <geometry>
                <cylinder radius="0.1" length="0.5"/>
            </geometry>
            <origin xyz="0.0 0.0 0.25" rpy="0.0 0.0 0.0"/>
        </collision>
        <inertial>
            <mass value="4.0"/>
            <origin xyz="0.0 0.0 0.25" rpy="0.0 0.0 0.0"/>
            <inertia ixx="0.093333296" ixy="0.0" ixz="0.0"
                     iyy="0.093333296" iyz="0.0"
                     izz="0.02"/>
        </inertial>
    </link>

    <joint name="Fifth_joint" type="continuous">
        <limit lower="-3.14" upper="3.14" effort="400.0" velocity="1.0"/>
        <parent link="Fourth"/>
        <child link="Fifth"/>
        <axis xyz="0 0 1"/>
        <origin xyz="0.0 0 0.5" rpy="0.0 0 0"/>
        <dynamics damping="0.7"/>
        <selfCollide>false</selfCollide> 
    </joint>

    <!-- SIXTH LINK-->
    <link name="Sixth">
        <visual>
            <geometry>
                <cylinder radius="0.075" length="0.29"/>
            </geometry>
            <material name="Orange">
                <color rgba="1.0 0.5 0.15 1.0"/>
            </material>
            <origin xyz="0.0 0.0 0.145" rpy="0.0 0.0 0.0"/>
        </visual>
        <collision>
            <geometry>
                <cylinder radius="0.075" length="0.29"/>
            </geometry>
            <origin xyz="0.0 0.0 0.145" rpy="0.0 0.0 0.0"/>
        </collision>
        <inertial>
            <mass value="1.0"/>
            <origin xyz="0.0 0.0 0.145" rpy="0.0 0.0 0.0"/>
            <inertia ixx="0.00841458" ixy="0.0" ixz="0.0"
                     iyy="0.00841458" iyz="0.0"
                     izz="0.0028125"/>
        </inertial>
    </link>

    <joint name="Sixth_joint" type="continuous">
        <limit lower="-3.14" upper="3.14" effort="300.0" velocity="1.0"/>
        <parent link="Fifth"/>
        <child link="Sixth"/>
        <axis xyz="0 1 0"/>
        <origin xyz="0.0 0 0.5" rpy="0.0 0 0"/>    
        <selfCollide>false</selfCollide>    
    </joint>


    <!-- GRIPPER_BASE LINK-->
    <link name="Gripper_Base">
        <visual>
            <geometry>
                <cylinder radius="0.1" length="0.05"/>
            </geometry>
            <material name="Black"/>
            <origin xyz="0.0 0.0 0.025" rpy="0.0 0.0 0.0"/>
        </visual>
        <collision>
            <geometry>
                <cylinder radius="0.08" length="0.05"/>
            </geometry>
            <origin xyz="0.0 0.0 0.025" rpy="0.0 0.0 0.0"/>
        </collision>
        <inertial>
            <mass value="0.3"/>
            <origin xyz="0.0 0.0 0.025" rpy="0.0 0.0 0.0"/>
            <inertia ixx="0.000270833" ixy="0.0" ixz="0.0"
                     iyy="0.000270833" iyz="0.0"
                     izz="0.0005"  />
        </inertial>
    </link>

    <joint name="Gripper_Base_joint" type="continuous">
        <limit lower="-3.14" upper="3.14" effort="200.0" velocity="1.0"/>
        <parent link="Sixth"/>
        <child link="Gripper_Base"/>
        <axis xyz="0.0 0.0 1"/>
        <origin xyz="0.0 0 0.29" rpy="0.0 0 0"/>
        <dynamics damping="0.7"/>
        <selfCollide>false</selfCollide>    
    </joint>

    <!-- LEFT FINGER LINK-->
    <link name="Left_Finger">
        <visual>
            <geometry>
                <box size="0.02 0.02 0.15"/>
            </geometry>
            <material name="Red">
                <color rgba="1.0 0.0 0.0 1.0"/>
            </material>
            <origin xyz="0.0 0.0 0.075" rpy="0.0 0.0 0.0"/>
        </visual>
        <collision>
            <geometry>
                <box size="0.02 0.02 0.15"/>
            </geometry>
            <origin xyz="0.0 0.0 0.075" rpy="0.0 0.0 0.0"/>
        </collision>
        <inertial>
            <mass value="0.05"/>
            <origin xyz="0.0 0.0 0.075" rpy="0.0 0.0 0.0"/>
            <inertia ixx="0.000095" ixy="0.0" ixz="0.0"
                     iyy="0.000095" iyz="0.0"
                     izz="0.0000025"/>
        </inertial>
    </link>

    <joint name="Left_Finger_joint" type="prismatic">
        <limit lower="-0.02" upper="0.02" effort="100.0" velocity="1.0"/>
        <parent link="Gripper_Base"/>
        <child link="Left_Finger"/>
        <axis xyz="0.0 1.0 0.0"/>
        <origin xyz="0.0 -0.04 0.05" />
        <dynamics damping="0.7"/>
        <selfCollide>false</selfCollide>   
    </joint>

    <!-- RIGHT FINGER LINK-->
    <link name="Right_Finger">
        <visual>
            <geometry>
                <box size="0.02 0.02 0.15"/>
            </geometry>
                <material name="Red">
                    <color rgba="1.0 0.0 0.0 1.0"/>
                </material>
            <origin xyz="0.0 0.0 0.075" rpy="0.0 0.0 0.0"/>
        </visual>
        <collision>
            <geometry>
                <box size="0.02 0.02 0.15"/>
            </geometry>
            <origin xyz="0.0 0.0 0.075" rpy="0.0 0.0 0.0"/>
        </collision>
        <inertial>
            <mass value="0.05"/>
            <origin xyz="0.0 0.0 0.075" rpy="0.0 0.0 0.0"/>
            <inertia ixx="0.000095" ixy="0.0" ixz="0.0"
                     iyy="0.000095" iyz="0.0"
                     izz="0.0000025"/>
        </inertial>
    </link>

    <joint name="Right_Finger_joint" type="prismatic">
        <limit lower="-0.02" upper="0.02" effort="100.0" velocity="1.0"/>
        <parent link="Gripper_Base"/>
        <child link="Right_Finger"/>
        <axis xyz="0.0 -1.0 0.0"/>
        <origin xyz="0.0 0.04 0.05" />
        <dynamics damping="0.7"/>
        <selfCollide>false</selfCollide>       
    </joint>

    
    <!--TRANSMISSIONS-->
    <!--First-->
    <transmission name ="Transmission_1">
        <type>transmission_interface/SimpleTransmission</type>
        <joint name="First_joint">
            <hardwareInterface>hardware_interface/PositionJointInterface</hardwareInterface>
        </joint>
        <actuator name="Motor1">
            <hardwareInterface>hardware_interface/PositionJointInterface</hardwareInterface>
            <mechanicalReduction>1</mechanicalReduction>
        </actuator>
    </transmission>

    <!--Third-->
    <transmission name ="Transmission_3">
        <type>transmission_interface/SimpleTransmission</type>
        <joint name="Third_joint">
            <hardwareInterface>hardware_interface/PositionJointInterface</hardwareInterface>
        </joint>
        <actuator name="Motor3">
            <hardwareInterface>hardware_interface/PositionJointInterface</hardwareInterface>
            <mechanicalReduction>1</mechanicalReduction>
        </actuator>
    </transmission>


    <!--Fourth-->
    <transmission name="Transmission_4">
        <type>transmission_interface/SimpleTransmission</type>
        <joint name="Fourth_joint">
            <hardwareInterface>hardware_interface/PositionJointInterface</hardwareInterface>
        </joint>
        <actuator name="Motor4">
            <hardwareInterface>hardware_interface/PositionJointInterface</hardwareInterface>
            <mechanicalReduction>1</mechanicalReduction>
        </actuator>
    </transmission>

    <!--Fifth-->
    <transmission name="Transmission_5">
        <type>transmission_interface/SimpleTransmission</type>
        <joint name="Fifth_joint">
            <hardwareInterface>hardware_interface/PositionJointInterface</hardwareInterface>
        </joint>
        <actuator name="Motor5">
            <hardwareInterface>hardware_interface/PositionJointInterface</hardwareInterface>
            <mechanicalReduction>1</mechanicalReduction>
        </actuator>
    </transmission>

    <!--Sixth-->
    <transmission name="Transmission_6">
        <type>transmission_interface/SimpleTransmission</type>
        <joint name="Sixth_joint">
            <hardwareInterface>hardware_interface/PositionJointInterface</hardwareInterface>
        </joint>
        <actuator name="Motor6">
            <hardwareInterface>hardware_interface/PositionJointInterface</hardwareInterface>
            <mechanicalReduction>1</mechanicalReduction>
        </actuator>
    </transmission>

    <!--Gripper base-->
    <transmission name="Transmission_7">
        <type>transmission_interface/SimpleTransmission</type>
        <joint name="Gripper_Base_joint">
            <hardwareInterface>hardware_interface/PositionJointInterface</hardwareInterface>
        </joint>
        <actuator name="Motor7">
            <hardwareInterface>hardware_interface/PositionJointInterface</hardwareInterface>
            <mechanicalReduction>1</mechanicalReduction>
        </actuator>
    </transmission>

    <!--Left finger-->
    <transmission name="Transmission_8">
        <type>transmission_interface/SimpleTransmission</type>
        <joint name="Left_Finger_joint">
            <hardwareInterface>hardware_interface/PositionJointInterface</hardwareInterface>
        </joint>
        <actuator name="Motor8">
            <hardwareInterface>hardware_interface/PositionJointInterface</hardwareInterface>
            <mechanicalReduction>1</mechanicalReduction>
        </actuator>
    </transmission>

    <!--Right finger-->
    <transmission name="Transmission_9">
        <type>transmission_interface/SimpleTransmission</type>
        <joint name="Right_Finger_joint">
            <hardwareInterface>hardware_interface/PositionJointInterface</hardwareInterface>
        </joint>
        <actuator name="Motor9">
            <hardwareInterface>hardware_interface/PositionJointInterface</hardwareInterface>
            <mechanicalReduction>1</mechanicalReduction>
        </actuator>
    </transmission>


    <gazebo>
        <plugin name="gazebo_ros_control" filename="libgazebo_ros_control.so">
            <robotNamespace>/robot_arm</robotNamespace>
        </plugin>
    </gazebo>        
    

    <gazebo>
        <plugin name="joint_state_publisher" filename="libgazebo_ros_joint_state_publisher.so">
            <robotNamespace>/robot_arm</robotNamespace>
            <jointName>First_joint, Third_joint, Fourth_joint, Fifth_joint, Sixth_joint, Gripper_Base_joint, Left_Finger_joint, Right_Finger_joint</jointName>
            <updateRate>50</updateRate>
        </plugin>
    </gazebo>

    <!-- RGBD camera -->
    <!--camera-->
    <link name='camera_link'>
        <pose>0 0 0 0 0 0</pose>
        <inertial>
        <mass value="0.1"/>
        <origin xyz="0 0 0" rpy=" 0 0 0"/>
        <inertia
            ixx="1e-6" ixy="0" ixz="0"
            iyy="1e-6" iyz="0"
            izz="1e-6"
        />
        </inertial>

        <collision name='collision'>
        <origin xyz="0 0 0" rpy=" 0 0 0"/> 
        <geometry>
            <box size=".05 .05 .05"/>
        </geometry>
        </collision>

        <visual name='camera_link_visual'>
        <origin xyz="0 0 0" rpy=" 0 0 0"/>
        <geometry>
            <box size=".05 .05 .05"/>
        </geometry>
        </visual>

    </link>

    <link name="camera_link_optical">
    </link>
    <joint type="fixed" name="camera_joint">
        <origin xyz="1.5 0 4.0" rpy="0 1.5707 0"/>
        <child link="camera_link"/>
        <parent link="base_link"/>
        <axis xyz="0 1 0" rpy="0 0 0"/>
    </joint>

    <joint type="fixed" name="camera_optical_joint">
        <origin xyz="0 0 0" rpy="-1.5707 0 -1.5707"/>
        <child link="camera_link_optical"/>
        <parent link="camera_link"/>
    </joint>

    <gazebo reference="camera_link">
        <sensor type="depth" name="camera1">
        <always_on>1</always_on>
        <update_rate>20.0</update_rate>
        <visualize>true</visualize>             
        <camera>
            <horizontal_fov>1.5</horizontal_fov>  
            <image>
            <width>640</width>
            <height>480</height>
            <format>B8G8R8</format>
            </image>
            <depth_camera>

            </depth_camera>
            <clip>
            <near>0.1</near>
            <far>20</far>
            </clip>
        </camera>
        <plugin name="camera_controller" filename="libgazebo_ros_openni_kinect.so">
            <alwaysOn>true</alwaysOn>
            <updateRate>10.0</updateRate>
            <cameraName>camera</cameraName>
            <frameName>camera_link_optical</frameName>                   
            <imageTopicName>rgb/image_raw</imageTopicName>
            <depthImageTopicName>depth/image_raw</depthImageTopicName>
            <pointCloudTopicName>depth/points</pointCloudTopicName>
            <cameraInfoTopicName>rgb/camera_info</cameraInfoTopicName>              
            <depthImageCameraInfoTopicName>depth/camera_info</depthImageCameraInfoTopicName>            
            <pointCloudCutoff>0.4</pointCloudCutoff>                
            <hackBaseline>0.07</hackBaseline>
            <distortionK1>0.0</distortionK1>
            <distortionK2>0.0</distortionK2>
            <distortionK3>0.0</distortionK3>
            <distortionT1>0.0</distortionT1>
            <distortionT2>0.0</distortionT2>
            <CxPrime>0.0</CxPrime>
            <Cx>0.0</Cx>
            <Cy>0.0</Cy>
            <focalLength>0.0</focalLength>
        </plugin>
        </sensor>
    </gazebo>


    <gazebo reference="base_link">
        <material>Gazebo/Black</material>
    </gazebo>

    <gazebo reference="First">
        <material>Gazebo/Orange</material>
    </gazebo>

    <gazebo reference="Second">
        <material>Gazebo/Orange</material>
    </gazebo>

    <gazebo reference="Third">
        <material>Gazebo/Orange</material>
    </gazebo>

    <gazebo reference="Fourth">
        <material>Gazebo/Orange</material>
    </gazebo>

    <gazebo reference="Fifth">
        <material>Gazebo/Orange</material>
    </gazebo>

    <gazebo reference="Sixth">
        <material>Gazebo/Orange</material>
    </gazebo>

    <gazebo reference="Gripper_Base">
        <material>Gazebo/Black</material>
    </gazebo>

    <gazebo reference="Left_Finger">
        <material>Gazebo/Red</material>
    </gazebo>

    <gazebo reference="Right_Finger">
        <material>Gazebo/Red</material>
    </gazebo>

</robot>
